Workbook

Sheet registo_ativo-CDs (1)
B1: ID | C1: Localização | D1: TAG | E1: Local | F1: COD_local | G1: ID_local | H1: instalação | I1: COD_instalacao | J1: ID_instalacao | K1: Sistema | L1: COD_sistema | M1: ID_sistema | N1: Grupo | O1: 0 | P1: ID_grupo | Q1: Equipamento | R1: COD_equipamento | S1: ID_equipamento | T1: Nº de Ordem | U1: Sector | V1: Marca / Fabricante | W1: Modelo / Características | X1: Criticidade | Y1: Estado | Z1: Nome | AA1: Data Instalação | AB1: Tempo nominal de vida útil (*) | AC1: Esperança de vida útil (anos (*) | AD1: Periodicidade | AE1: Especificação | AG1: Imagem | AH1: Path_Imagen | AI1: Data_Inicio_Manutencao
A2: =LEN(B2) -> 15 | B2: =CONCATENATE(G2,J2,M2,P2,S2,T2) -> CD28BBG131BOM01 | C2: =CONCATENATE(F2, "-", I2, "-", L2, "-", O2, "-", R2, "-", T2) -> CD-CHA-BBG-EBC-BOM-01 | E2: Centro distribuidor | F2: =VLOOKUP(E2,Localizacoes!$A$3:$B$100,2,FALSE) -> CD | G2: =VLOOKUP(E2,ID!$A$3:$B$100,2,FALSE) -> CD | H2: Chamanculo | I2: =VLOOKUP(H2,Localizacoes!$C$3:$D$100,2,FALSE) -> CHA | J2: =VLOOKUP(H2,ID!$C$3:$D$100,2,FALSE) -> 28 | K2: Bombagem | L2: =VLOOKUP(K2,Localizacoes!$E$3:$F$100,2,FALSE) -> BBG | M2: =VLOOKUP(K2,ID!$E$3:$F$100,2,FALSE) -> BBG | N2: Electrobomba centrífuga | O2: =VLOOKUP(N2,Localizacoes!$G$3:$H$100,2,FALSE) -> EBC | P2: =VLOOKUP(N2,ID!$G$3:$H$100,2,FALSE) -> 131 | Q2: Bomba | R2: =VLOOKUP(Q2,Localizacoes!$I$3:$J$100,2,FALSE) -> BOM | S2: =VLOOKUP(Q2,ID!$I$3:$J$100,2,FALSE) -> BOM | T2: 01 | U2: Mecânica | V2: EMICA | X2: Critico | Y2: Operacional | Z2: =Q2&" "& T2 -> Bomba 01 | AA2: 2024 | AD2: Mensal | AF2: =_xlfn.CONCAT(N2,Q2) -> Electrobomba centrífugaBomba | AG2: =VLOOKUP(AF2,Imagens!$C$2:$D$42,2,FALSE) -> 65e96125c1d11 | AH2: =_xlfn.CONCAT(Imagens!$H$2,'registo_ativo-CDs (1)'!AG2) -> assets/imagens/products/65e96125c1d11 | AI2: 45310
A3: =LEN(B3) -> 15 | B3: =CONCATENATE(G3,J3,M3,P3,S3,T3) -> CD28BBG131MOT01 | C3: =CONCATENATE(F3, "-", I3, "-", L3, "-", O3, "-", R3, "-", T3) -> CD-CHA-BBG-EBC-MOT-01 | E3: Centro distribuidor | F3: =VLOOKUP(E3,Localizacoes!$A$3:$B$100,2,FALSE) -> CD | G3: =VLOOKUP(E3,ID!$A$3:$B$100,2,FALSE) -> CD | H3: Chamanculo | I3: =VLOOKUP(H3,Localizacoes!$C$3:$D$100,2,FALSE) -> CHA | J3: =VLOOKUP(H3,ID!$C$3:$D$100,2,FALSE) -> 28 | K3: Bombagem | L3: =VLOOKUP(K3,Localizacoes!$E$3:$F$100,2,FALSE) -> BBG | M3: =VLOOKUP(K3,ID!$E$3:$F$100,2,FALSE) -> BBG | N3: Electrobomba centrífuga | O3: =VLOOKUP(N3,Localizacoes!$G$3:$H$100,2,FALSE) -> EBC | P3: =VLOOKUP(N3,ID!$G$3:$H$100,2,FALSE) -> 131 | Q3: Motor | R3: =VLOOKUP(Q3,Localizacoes!$I$3:$J$100,2,FALSE) -> MOT | S3: =VLOOKUP(Q3,ID!$I$3:$J$100,2,FALSE) -> MOT | T3: 01 | U3: Eléctrica | V3: ECHTOP | W3: Serial No:355Y0C0816-01;200kw,3000 V;46.5A;Conn:Y; 1487 R/Min;50Hz;Eff:95.4%;factor de Pontencia 0.868 | X3: Critico | Y3: Operacional | Z3: =Q3&" "& T3 -> Motor 01 | AA3: 2024 | AD3: Mensal | AF3: =_xlfn.CONCAT(N3,Q3) -> Electrobomba centrífugaMotor | AG3: =VLOOKUP(AF3,Imagens!$C$2:$D$42,2,FALSE) -> 65d04210323a4 | AH3: =_xlfn.CONCAT(Imagens!$H$2,'registo_ativo-CDs (1)'!AG3) -> assets/imagens/products/65d04210323a4 | AI3: 45310
A4: =LEN(B4) -> 15 | B4: =CONCATENATE(G4,J4,M4,P4,S4,T4) -> CD28BBG131QEA01 | C4: =CONCATENATE(F4, "-", I4, "-", L4, "-", O4, "-", R4, "-", T4) -> CD-CHA-BBG-EBC-QEA-01 | E4: Centro distribuidor | F4: =VLOOKUP(E4,Localizacoes!$A$3:$B$100,2,FALSE) -> CD | G4: =VLOOKUP(E4,ID!$A$3:$B$100,2,FALSE) -> CD | H4: Chamanculo | I4: =VLOOKUP(H4,Localizacoes!$C$3:$D$100,2,FALSE) -> CHA | J4: =VLOOKUP(H4,ID!$C$3:$D$100,2,FALSE) -> 28 | K4: Bombagem | L4: =VLOOKUP(K4,Localizacoes!$E$3:$F$100,2,FALSE) -> BBG | M4: =VLOOKUP(K4,ID!$E$3:$F$100,2,FALSE) -> BBG | N4: Electrobomba centrífuga | O4: =VLOOKUP(N4,Localizacoes!$G$3:$H$100,2,FALSE) -> EBC | P4: =VLOOKUP(N4,ID!$G$3:$H$100,2,FALSE) -> 131 | Q4: Quadros Eléctricos de Arranque | R4: =VLOOKUP(Q4,Localizacoes!$I$3:$J$100,2,FALSE) -> QEA | S4: =VLOOKUP(Q4,ID!$I$3:$J$100,2,FALSE) -> QEA | T4: 01 | U4: Eléctrica | X4: Critico | Y4: Operacional | Z4: =Q4&" "& T4 -> Quadros Eléctricos de Arranque 01 | AA4: 2024 | AD4: Trimestral | AF4: =_xlfn.CONCAT(N4,Q4) -> Electrobomba centrífugaQuadros Eléctricos de Arranque | AG4: =VLOOKUP(AF4,Imagens!$C$2:$D$42,2,FALSE) -> 65e8d2fa35c12 | AH4: =_xlfn.CONCAT(Imagens!$H$2,'registo_ativo-CDs (1)'!AG4) -> assets/imagens/products/65e8d2fa35c12 | AI4: 45366
A5: =LEN(B5) -> 15 | B5: =CONCATENATE(G5,J5,M5,P5,S5,T5) -> CD28BBG131VSU01 | C5: =CONCATENATE(F5, "-", I5, "-", L5, "-", O5, "-", R5, "-", T5) -> CD-CHA-BBG-EBC-VSU-01 | E5: Centro distribuidor | F5: =VLOOKUP(E5,Localizacoes!$A$3:$B$100,2,FALSE) -> CD | G5: =VLOOKUP(E5,ID!$A$3:$B$100,2,FALSE) -> CD | H5: Chamanculo | I5: =VLOOKUP(H5,Localizacoes!$C$3:$D$100,2,FALSE) -> CHA | J5: =VLOOKUP(H5,ID!$C$3:$D$100,2,FALSE) -> 28 | K5: Bombagem | L5: =VLOOKUP(K5,Localizacoes!$E$3:$F$100,2,FALSE) -> BBG | M5: =VLOOKUP(K5,ID!$E$3:$F$100,2,FALSE) -> BBG | N5: Electrobomba centrífuga | O5: =VLOOKUP(N5,Localizacoes!$G$3:$H$100,2,FALSE) -> EBC | P5: =VLOOKUP(N5,ID!$G$3:$H$100,2,FALSE) -> 131 | Q5: Válvula Sucção | R5: =VLOOKUP(Q5,Localizacoes!$I$3:$J$100,2,FALSE) -> VSU | S5: =VLOOKUP(Q5,ID!$I$3:$J$100,2,FALSE) -> VSU | T5: 01 | U5: Mecânica | X5: Critico | Y5: Operacional | Z5: =Q5&" "& T5 -> Válvula Sucção 01 | AA5: 2024 | AD5: Trimestral | AF5: =_xlfn.CONCAT(N5,Q5) -> Electrobomba centrífugaVálvula Sucção | AG5: =VLOOKUP(AF5,Imagens!$C$2:$D$42,2,FALSE) -> 65e8cda0676b7 | AH5: =_xlfn.CONCAT(Imagens!$H$2,'registo_ativo-CDs (1)'!AG5) -> assets/imagens/products/65e8cda0676b7 | AI5: 45366
A6: =LEN(B6) -> 15 | B6: =CONCATENATE(G6,J6,M6,P6,S6,T6) -> CD28BBG131VDE01 | C6: =CONCATENATE(F6, "-", I6, "-", L6, "-", O6, "-", R6, "-", T6) -> CD-CHA-BBG-EBC-VDE-01 | E6: Centro distribuidor | F6: =VLOOKUP(E6,Localizacoes!$A$3:$B$100,2,FALSE) -> CD | G6: =VLOOKUP(E6,ID!$A$3:$B$100,2,FALSE) -> CD | H6: Chamanculo | I6: =VLOOKUP(H6,Localizacoes!$C$3:$D$100,2,FALSE) -> CHA | J6: =VLOOKUP(H6,ID!$C$3:$D$100,2,FALSE) -> 28 | K6: Bombagem | L6: =VLOOKUP(K6,Localizacoes!$E$3:$F$100,2,FALSE) -> BBG | M6: =VLOOKUP(K6,ID!$E$3:$F$100,2,FALSE) -> BBG | N6: Electrobomba centrífuga | O6: =VLOOKUP(N6,Localizacoes!$G$3:$H$100,2,FALSE) -> EBC | P6: =VLOOKUP(N6,ID!$G$3:$H$100,2,FALSE) -> 131 | Q6: Válvula Descarga | R6: =VLOOKUP(Q6,Localizacoes!$I$3:$J$100,2,FALSE) -> VDE | S6: =VLOOKUP(Q6,ID!$I$3:$J$100,2,FALSE) -> VDE | T6: 01 | U6: Mecânica | X6: Critico | Y6: Operacional | Z6: =Q6&" "& T6 -> Válvula Descarga 01 | AA6: 2024 | AD6: Trimestral | AF6: =_xlfn.CONCAT(N6,Q6) -> Electrobomba centrífugaVálvula Descarga | AG6: =VLOOKUP(AF6,Imagens!$C$2:$D$42,2,FALSE) -> 65e8cda0676b7 | AH6: =_xlfn.CONCAT(Imagens!$H$2,'registo_ativo-CDs (1)'!AG6) -> assets/imagens/products/65e8cda0676b7 | AI6: 45366
A7: =LEN(B7) -> 15 | B7: =CONCATENATE(G7,J7,M7,P7,S7,T7) -> CD28BBG131BOM02 | C7: =CONCATENATE(F7, "-", I7, "-", L7, "-", O7, "-", R7, "-", T7) -> CD-CHA-BBG-EBC-BOM-02 | E7: Centro distribuidor | F7: =VLOOKUP(E7,Localizacoes!$A$3:$B$100,2,FALSE) -> CD | G7: =VLOOKUP(E7,ID!$A$3:$B$100,2,FALSE) -> CD | H7: Chamanculo | I7: =VLOOKUP(H7,Localizacoes!$C$3:$D$100,2,FALSE) -> CHA | J7: =VLOOKUP(H7,ID!$C$3:$D$100,2,FALSE) -> 28 | K7: Bombagem | L7: =VLOOKUP(K7,Localizacoes!$E$3:$F$100,2,FALSE) -> BBG | M7: =VLOOKUP(K7,ID!$E$3:$F$100,2,FALSE) -> BBG | N7: Electrobomba centrífuga | O7: =VLOOKUP(N7,Localizacoes!$G$3:$H$100,2,FALSE) -> EBC | P7: =VLOOKUP(N7,ID!$G$3:$H$100,2,FALSE) -> 131 | Q7: Bomba | R7: =VLOOKUP(Q7,Localizacoes!$I$3:$J$100,2,FALSE) -> BOM | S7: =VLOOKUP(Q7,ID!$I$3:$J$100,2,FALSE) -> BOM | T7: 02 | U7: Mecânica | V7: Grundfos | W7: HS350-250-498/422 5/3-FA-BBVP 2*Model: 98607941P114130001* 1750 m³/h* 40 m* 1480 rpm* 78,8%*16/100 bar/°Cmax* | X7: Critico | Y7: Operacional | Z7: =Q7&" "& T7 -> Bomba 02 | AA7: 2017 | AD7: Mensal | AF7: =_xlfn.CONCAT(N7,Q7) -> Electrobomba centrífugaBomba | AG7: =VLOOKUP(AF7,Imagens!$C$2:$D$42,2,FALSE) -> 65e96125c1d11 | AH7: =_xlfn.CONCAT(Imagens!$H$2,'registo_ativo-CDs (1)'!AG7) -> assets/imagens/products/65e96125c1d11 | AI7: 45310
A8: =LEN(B8) -> 15 | B8: =CONCATENATE(G8,J8,M8,P8,S8,T8) -> CD28BBG131MOT02 | C8: =CONCATENATE(F8, "-", I8, "-", L8, "-", O8, "-", R8, "-", T8) -> CD-CHA-BBG-EBC-MOT-02 | E8: Centro distribuidor | F8: =VLOOKUP(E8,Localizacoes!$A$3:$B$100,2,FALSE) -> CD | G8: =VLOOKUP(E8,ID!$A$3:$B$100,2,FALSE) -> CD | H8: Chamanculo | I8: =VLOOKUP(H8,Localizacoes!$C$3:$D$100,2,FALSE) -> CHA | J8: =VLOOKUP(H8,ID!$C$3:$D$100,2,FALSE) -> 28 | K8: Bombagem | L8: =VLOOKUP(K8,Localizacoes!$E$3:$F$100,2,FALSE) -> BBG | M8: =VLOOKUP(K8,ID!$E$3:$F$100,2,FALSE) -> BBG | N8: Electrobomba centrífuga | O8: =VLOOKUP(N8,Localizacoes!$G$3:$H$100,2,FALSE) -> EBC | P8: =VLOOKUP(N8,ID!$G$3:$H$100,2,FALSE) -> 131 | Q8: Motor | R8: =VLOOKUP(Q8,Localizacoes!$I$3:$J$100,2,FALSE) -> MOT | S8: =VLOOKUP(Q8,ID!$I$3:$J$100,2,FALSE) -> MOT | T8: 02 | U8: Eléctrica | V8: ABB | W8: 400v; 50 Hz; 551 A; Kw 315; cosΦ:0.86. 1488 rpm. 3̃ ˜Mot. 1LA4.312- 4AN34-Z; rotor: SQUCQGE; THCI/6. IP55. N⁰: U1188395010006/2006N/N1* Rolamento 6322/C3 & 6316/C3 | X8: Critico | Y8: Operacional | Z8: =Q8&" "& T8 -> Motor 02 | AA8: 2017 | AD8: Mensal | AF8: =_xlfn.CONCAT(N8,Q8) -> Electrobomba centrífugaMotor | AG8: =VLOOKUP(AF8,Imagens!$C$2:$D$42,2,FALSE) -> 65d04210323a4 | AH8: =_xlfn.CONCAT(Imagens!$H$2,'registo_ativo-CDs (1)'!AG8) -> assets/imagens/products/65d04210323a4 | AI8: 45310
A9: =LEN(B9) -> 15 | B9: =CONCATENATE(G9,J9,M9,P9,S9,T9) -> CD28BBG131QEA02 | C9: =CONCATENATE(F9, "-", I9, "-", L9, "-", O9, "-", R9, "-", T9) -> CD-CHA-BBG-EBC-QEA-02 | E9: Centro distribuidor | F9: =VLOOKUP(E9,Localizacoes!$A$3:$B$100,2,FALSE) -> CD | G9: =VLOOKUP(E9,ID!$A$3:$B$100,2,FALSE) -> CD | H9: Chamanculo | I9: =VLOOKUP(H9,Localizacoes!$C$3:$D$100,2,FALSE) -> CHA | J9: =VLOOKUP(H9,ID!$C$3:$D$100,2,FALSE) -> 28 | K9: Bombagem | L9: =VLOOKUP(K9,Localizacoes!$E$3:$F$100,2,FALSE) -> BBG | M9: =VLOOKUP(K9,ID!$E$3:$F$100,2,FALSE) -> BBG | N9: Electrobomba centrífuga | O9: =VLOOKUP(N9,Localizacoes!$G$3:$H$100,2,FALSE) -> EBC | P9: =VLOOKUP(N9,ID!$G$3:$H$100,2,FALSE) -> 131 | Q9: Quadros Eléctricos de Arranque | R9: =VLOOKUP(Q9,Localizacoes!$I$3:$J$100,2,FALSE) -> QEA | S9: =VLOOKUP(Q9,ID!$I$3:$J$100,2,FALSE) -> QEA | T9: 02 | U9: Eléctrica | Y9: Operacional | Z9: =Q9&" "& T9 -> Quadros Eléctricos de Arranque 02 | AA9: 2017 | AD9: Trimestral | AF9: =_xlfn.CONCAT(N9,Q9) -> Electrobomba centrífugaQuadros Eléctricos de Arranque | AG9: =VLOOKUP(AF9,Imagens!$C$2:$D$42,2,FALSE) -> 65e8d2fa35c12 | AH9: =_xlfn.CONCAT(Imagens!$H$2,'registo_ativo-CDs (1)'!AG9) -> assets/imagens/products/65e8d2fa35c12 | AI9: 45366
A10: =LEN(B10) -> 15 | B10: =CONCATENATE(G10,J10,M10,P10,S10,T10) -> CD28BBG131VSU02 | C10: =CONCATENATE(F10, "-", I10, "-", L10, "-", O10, "-", R10, "-", T10) -> CD-CHA-BBG-EBC-VSU-02 | E10: Centro distribuidor | F10: =VLOOKUP(E10,Localizacoes!$A$3:$B$100,2,FALSE) -> CD | G10: =VLOOKUP(E10,ID!$A$3:$B$100,2,FALSE) -> CD | H10: Chamanculo | I10: =VLOOKUP(H10,Localizacoes!$C$3:$D$100,2,FALSE) -> CHA | J10: =VLOOKUP(H10,ID!$C$3:$D$100,2,FALSE) -> 28 | K10: Bombagem | L10: =VLOOKUP(K10,Localizacoes!$E$3:$F$100,2,FALSE) -> BBG | M10: =VLOOKUP(K10,ID!$E$3:$F$100,2,FALSE) -> BBG | N10: Electrobomba centrífuga | O10: =VLOOKUP(N10,Localizacoes!$G$3:$H$100,2,FALSE) -> EBC | P10: =VLOOKUP(N10,ID!$G$3:$H$100,2,FALSE) -> 131 | Q10: Válvula Sucção | R10: =VLOOKUP(Q10,Localizacoes!$I$3:$J$100,2,FALSE) -> VSU | S10: =VLOOKUP(Q10,ID!$I$3:$J$100,2,FALSE) -> VSU | T10: 02 | U10: Mecânica | Y10: Operacional | Z10: =Q10&" "& T10 -> Válvula Sucção 02 | AA10: 2017 | AD10: Trimestral | AF10: =_xlfn.CONCAT(N10,Q10) -> Electrobomba centrífugaVálvula Sucção | AG10: =VLOOKUP(AF10,Imagens!$C$2:$D$42,2,FALSE) -> 65e8cda0676b7 | AH10: =_xlfn.CONCAT(Imagens!$H$2,'registo_ativo-CDs (1)'!AG10) -> assets/imagens/products/65e8cda0676b7 | AI10: 45366
A11: =LEN(B11) -> 15 | B11: =CONCATENATE(G11,J11,M11,P11,S11,T11) -> CD28BBG131VDE02 | C11: =CONCATENATE(F11, "-", I11, "-", L11, "-", O11, "-", R11, "-", T11) -> CD-CHA-BBG-EBC-VDE-02 | E11: Centro distribuidor | F11: =VLOOKUP(E11,Localizacoes!$A$3:$B$100,2,FALSE) -> CD | G11: =VLOOKUP(E11,ID!$A$3:$B$100,2,FALSE) -> CD | H11: Chamanculo | I11: =VLOOKUP(H11,Localizacoes!$C$3:$D$100,2,FALSE) -> CHA | J11: =VLOOKUP(H11,ID!$C$3:$D$100,2,FALSE) -> 28 | K11: Bombagem | L11: =VLOOKUP(K11,Localizacoes!$E$3:$F$100,2,FALSE) -> BBG | M11: =VLOOKUP(K11,ID!$E$3:$F$100,2,FALSE) -> BBG | N11: Electrobomba centrífuga | O11: =VLOOKUP(N11,Localizacoes!$G$3:$H$100,2,FALSE) -> EBC | P11: =VLOOKUP(N11,ID!$G$3:$H$100,2,FALSE) -> 131 | Q11: Válvula Descarga | R11: =VLOOKUP(Q11,Localizacoes!$I$3:$J$100,2,FALSE) -> VDE | S11: =VLOOKUP(Q11,ID!$I$3:$J$100,2,FALSE) -> VDE | T11: 02 | U11: Mecânica | X11: Redundância | Y11: Operacional | Z11: =Q11&" "& T11 -> Válvula Descarga 02 | AA11: 2017 | AD11: Trimestral | AF11: =_xlfn.CONCAT(N11,Q11) -> Electrobomba centrífugaVálvula Descarga | AG11: =VLOOKUP(AF11,Imagens!$C$2:$D$42,2,FALSE) -> 65e8cda0676b7 | AH11: =_xlfn.CONCAT(Imagens!$H$2,'registo_ativo-CDs (1)'!AG11) -> assets/imagens/products/65e8cda0676b7 | AI11: 45366
A12: =LEN(B12) -> 15 | B12: =CONCATENATE(G12,J12,M12,P12,S12,T12) -> CD28BBG131AEL02 | C12: =CONCATENATE(F12, "-", I12, "-", L12, "-", O12, "-", R12, "-", T12) -> CD-CHA-BBG-EBC-AEL-02 | E12: Centro distribuidor | F12: =VLOOKUP(E12,Localizacoes!$A$3:$B$100,2,FALSE) -> CD | G12: =VLOOKUP(E12,ID!$A$3:$B$100,2,FALSE) -> CD | H12: Chamanculo | I12: =VLOOKUP(H12,Localizacoes!$C$3:$D$100,2,FALSE) -> CHA | J12: =VLOOKUP(H12,ID!$C$3:$D$100,2,FALSE) -> 28 | K12: Bombagem | L12: =VLOOKUP(K12,Localizacoes!$E$3:$F$100,2,FALSE) -> BBG | M12: =VLOOKUP(K12,ID!$E$3:$F$100,2,FALSE) -> BBG | N12: Electrobomba centrífuga | O12: =VLOOKUP(N12,Localizacoes!$G$3:$H$100,2,FALSE) -> EBC | P12: =VLOOKUP(N12,ID!$G$3:$H$100,2,FALSE) -> 131 | Q12: Actuador Eléctrico | R12: =VLOOKUP(Q12,Localizacoes!$I$3:$J$100,2,FALSE) -> AEL | S12: =VLOOKUP(Q12,ID!$I$3:$J$100,2,FALSE) -> AEL | T12: 02 | U12: Eléctrica | Y12: Operacional | Z12: =Q12&" "& T12 -> Actuador Eléctrico 02 | AA12: 2017 | AD12: Trimestral | AF12: =_xlfn.CONCAT(N12,Q12) -> Electrobomba centrífugaActuador Eléctrico | AG12: =VLOOKUP(AF12,Imagens!$C$2:$D$42,2,FALSE) -> 65e8db8f62d7b | AH12: =_xlfn.CONCAT(Imagens!$H$2,'registo_ativo-CDs (1)'!AG12) -> assets/imagens/products/65e8db8f62d7b | AI12: 46461
A13: =LEN(B13) -> 15 | B13: =CONCATENATE(G13,J13,M13,P13,S13,T13) -> CD28BBG131BOM05 | C13: =CONCATENATE(F13, "-", I13, "-", L13, "-", O13, "-", R13, "-", T13) -> CD-CHA-BBG-EBC-BOM-05 | E13: Centro distribuidor | F13: =VLOOKUP(E13,Localizacoes!$A$3:$B$100,2,FALSE) -> CD | G13: =VLOOKUP(E13,ID!$A$3:$B$100,2,FALSE) -> CD | H13: Chamanculo | I13: =VLOOKUP(H13,Localizacoes!$C$3:$D$100,2,FALSE) -> CHA | J13: =VLOOKUP(H13,ID!$C$3:$D$100,2,FALSE) -> 28 | K13: Bombagem | L13: =VLOOKUP(K13,Localizacoes!$E$3:$F$100,2,FALSE) -> BBG | M13: =VLOOKUP(K13,ID!$E$3:$F$100,2,FALSE) -> BBG | N13: Electrobomba centrífuga | O13: =VLOOKUP(N13,Localizacoes!$G$3:$H$100,2,FALSE) -> EBC | P13: =VLOOKUP(N13,ID!$G$3:$H$100,2,FALSE) -> 131 | Q13: Bomba | R13: =VLOOKUP(Q13,Localizacoes!$I$3:$J$100,2,FALSE) -> BOM | S13: =VLOOKUP(Q13,ID!$I$3:$J$100,2,FALSE) -> BOM | T13: 05 | U13: Mecânica | V13: Mather & Platt | W13: type: 10J2MLMED.3670-GPM* h37m* 1000m3/h. Rolamento 6314 | Y13: Operacional | Z13: =Q13&" "& T13 -> Bomba 05 | AA13: 1971 | AD13: Mensal | AF13: =_xlfn.CONCAT(N13,Q13) -> Electrobomba centrífugaBomba | AG13: =VLOOKUP(AF13,Imagens!$C$2:$D$42,2,FALSE) -> 65e96125c1d11 | AH13: =_xlfn.CONCAT(Imagens!$H$2,'registo_ativo-CDs (1)'!AG13) -> assets/imagens/products/65e96125c1d11 | AI13: 45310
A14: =LEN(B14) -> 15 | B14: =CONCATENATE(G14,J14,M14,P14,S14,T14) -> CD28BBG131MOT05 | C14: =CONCATENATE(F14, "-", I14, "-", L14, "-", O14, "-", R14, "-", T14) -> CD-CHA-BBG-EBC-MOT-05 | E14: Centro distribuidor | F14: =VLOOKUP(E14,Localizacoes!$A$3:$B$100,2,FALSE) -> CD | G14: =VLOOKUP(E14,ID!$A$3:$B$100,2,FALSE) -> CD | H14: Chamanculo | I14: =VLOOKUP(H14,Localizacoes!$C$3:$D$100,2,FALSE) -> CHA | J14: =VLOOKUP(H14,ID!$C$3:$D$100,2,FALSE) -> 28 | K14: Bombagem | L14: =VLOOKUP(K14,Localizacoes!$E$3:$F$100,2,FALSE) -> BBG | M14: =VLOOKUP(K14,ID!$E$3:$F$100,2,FALSE) -> BBG | N14: Electrobomba centrífuga | O14: =VLOOKUP(N14,Localizacoes!$G$3:$H$100,2,FALSE) -> EBC | P14: =VLOOKUP(N14,ID!$G$3:$H$100,2,FALSE) -> 131 | Q14: Motor | R14: =VLOOKUP(Q14,Localizacoes!$I$3:$J$100,2,FALSE) -> MOT | S14: =VLOOKUP(Q14,ID!$I$3:$J$100,2,FALSE) -> MOT | T14: 05 | U14: Eléctrica | V14: Mather & Platt | W14: 846089/1; size: DA365LA; R/M: 1475; AMPS: 5555; H250; Kw: 225; PT-85; Temp: 80⁰C; year: 1984; 1219 KG; brig. NE: REPN320N/C3; Brig NDE: RHPOR SKF 6310 C3K≠N320CS; 3000V. Rolamento 6320 ou N 320 | Y14: Operacional | Z14: =Q14&" "& T14 -> Motor 05 | AA14: 1971 | AD14: Mensal | AF14: =_xlfn.CONCAT(N14,Q14) -> Electrobomba centrífugaMotor | AG14: =VLOOKUP(AF14,Imagens!$C$2:$D$42,2,FALSE) -> 65d04210323a4 | AH14: =_xlfn.CONCAT(Imagens!$H$2,'registo_ativo-CDs (1)'!AG14) -> assets/imagens/products/65d04210323a4 | AI14: 45310
A15: =LEN(B15) -> 15 | B15: =CONCATENATE(G15,J15,M15,P15,S15,T15) -> CD28BBG131QEA05 | C15: =CONCATENATE(F15, "-", I15, "-", L15, "-", O15, "-", R15, "-", T15) -> CD-CHA-BBG-EBC-QEA-05 | E15: Centro distribuidor | F15: =VLOOKUP(E15,Localizacoes!$A$3:$B$100,2,FALSE) -> CD | G15: =VLOOKUP(E15,ID!$A$3:$B$100,2,FALSE) -> CD | H15: Chamanculo | I15: =VLOOKUP(H15,Localizacoes!$C$3:$D$100,2,FALSE) -> CHA | J15: =VLOOKUP(H15,ID!$C$3:$D$100,2,FALSE) -> 28 | K15: Bombagem | L15: =VLOOKUP(K15,Localizacoes!$E$3:$F$100,2,FALSE) -> BBG | M15: =VLOOKUP(K15,ID!$E$3:$F$100,2,FALSE) -> BBG | N15: Electrobomba centrífuga | O15: =VLOOKUP(N15,Localizacoes!$G$3:$H$100,2,FALSE) -> EBC | P15: =VLOOKUP(N15,ID!$G$3:$H$100,2,FALSE) -> 131 | Q15: Quadros Eléctricos de Arranque | R15: =VLOOKUP(Q15,Localizacoes!$I$3:$J$100,2,FALSE) -> QEA | S15: =VLOOKUP(Q15,ID!$I$3:$J$100,2,FALSE) -> QEA | T15: 05 | U15: Eléctrica | X15: Critico | Y15: Operacional | Z15: =Q15&" "& T15 -> Quadros Eléctricos de Arranque 05 | AA15: 1971 | AD15: Trimestral | AF15: =_xlfn.CONCAT(N15,Q15) -> Electrobomba centrífugaQuadros Eléctricos de Arranque | AG15: =VLOOKUP(AF15,Imagens!$C$2:$D$42,2,FALSE) -> 65e8d2fa35c12 | AH15: =_xlfn.CONCAT(Imagens!$H$2,'registo_ativo-CDs (1)'!AG15) -> assets/imagens/products/65e8d2fa35c12 | AI15: 45366
A16: =LEN(B16) -> 15 | B16: =CONCATENATE(G16,J16,M16,P16,S16,T16) -> CD28BBG131VSU05 | C16: =CONCATENATE(F16, "-", I16, "-", L16, "-", O16, "-", R16, "-", T16) -> CD-CHA-BBG-EBC-VSU-05 | E16: Centro distribuidor | F16: =VLOOKUP(E16,Localizacoes!$A$3:$B$100,2,FALSE) -> CD | G16: =VLOOKUP(E16,ID!$A$3:$B$100,2,FALSE) -> CD | H16: Chamanculo | I16: =VLOOKUP(H16,Localizacoes!$C$3:$D$100,2,FALSE) -> CHA | J16: =VLOOKUP(H16,ID!$C$3:$D$100,2,FALSE) -> 28 | K16: Bombagem | L16: =VLOOKUP(K16,Localizacoes!$E$3:$F$100,2,FALSE) -> BBG | M16: =VLOOKUP(K16,ID!$E$3:$F$100,2,FALSE) -> BBG | N16: Electrobomba centrífuga | O16: =VLOOKUP(N16,Localizacoes!$G$3:$H$100,2,FALSE) -> EBC | P16: =VLOOKUP(N16,ID!$G$3:$H$100,2,FALSE) -> 131 | Q16: Válvula Sucção | R16: =VLOOKUP(Q16,Localizacoes!$I$3:$J$100,2,FALSE) -> VSU | S16: =VLOOKUP(Q16,ID!$I$3:$J$100,2,FALSE) -> VSU | T16: 05 | U16: Mecânica | Y16: Operacional | Z16: =Q16&" "& T16 -> Válvula Sucção 05 | AA16: 1971 | AD16: Trimestral | AF16: =_xlfn.CONCAT(N16,Q16) -> Electrobomba centrífugaVálvula Sucção | AG16: =VLOOKUP(AF16,Imagens!$C$2:$D$42,2,FALSE) -> 65e8cda0676b7 | AH16: =_xlfn.CONCAT(Imagens!$H$2,'registo_ativo-CDs (1)'!AG16) -> assets/imagens/products/65e8cda0676b7 | AI16: 45366
A17: =LEN(B17) -> 15 | B17: =CONCATENATE(G17,J17,M17,P17,S17,T17) -> CD28BBG131VDE05 | C17: =CONCATENATE(F17, "-", I17, "-", L17, "-", O17, "-", R17, "-", T17) -> CD-CHA-BBG-EBC-VDE-05 | E17: Centro distribuidor | F17: =VLOOKUP(E17,Localizacoes!$A$3:$B$100,2,FALSE) -> CD | G17: =VLOOKUP(E17,ID!$A$3:$B$100,2,FALSE) -> CD | H17: Chamanculo | I17: =VLOOKUP(H17,Localizacoes!$C$3:$D$100,2,FALSE) -> CHA | J17: =VLOOKUP(H17,ID!$C$3:$D$100,2,FALSE) -> 28 | K17: Bombagem | L17: =VLOOKUP(K17,Localizacoes!$E$3:$F$100,2,FALSE) -> BBG | M17: =VLOOKUP(K17,ID!$E$3:$F$100,2,FALSE) -> BBG | N17: Electrobomba centrífuga | O17: =VLOOKUP(N17,Localizacoes!$G$3:$H$100,2,FALSE) -> EBC | P17: =VLOOKUP(N17,ID!$G$3:$H$100,2,FALSE) -> 131 | Q17: Válvula Descarga | R17: =VLOOKUP(Q17,Localizacoes!$I$3:$J$100,2,FALSE) -> VDE | S17: =VLOOKUP(Q17,ID!$I$3:$J$100,2,FALSE) -> VDE | T17: 05 | U17: Mecânica | Y17: Operacional | Z17: =Q17&" "& T17 -> Válvula Descarga 05 | AA17: 1971 | AD17: Trimestral | AF17: =_xlfn.CONCAT(N17,Q17) -> Electrobomba centrífugaVálvula Descarga | AG17: =VLOOKUP(AF17,Imagens!$C$2:$D$42,2,FALSE) -> 65e8cda0676b7 | AH17: =_xlfn.CONCAT(Imagens!$H$2,'registo_ativo-CDs (1)'!AG17) -> assets/imagens/products/65e8cda0676b7 | AI17: 45366
A18: =LEN(B18) -> 15 | B18: =CONCATENATE(G18,J18,M18,P18,S18,T18) -> CD28BBG131BOM06 | C18: =CONCATENATE(F18, "-", I18, "-", L18, "-", O18, "-", R18, "-", T18) -> CD-CHA-BBG-EBC-BOM-06 | E18: Centro distribuidor | F18: =VLOOKUP(E18,Localizacoes!$A$3:$B$100,2,FALSE) -> CD | G18: =VLOOKUP(E18,ID!$A$3:$B$100,2,FALSE) -> CD | H18: Chamanculo | I18: =VLOOKUP(H18,Localizacoes!$C$3:$D$100,2,FALSE) -> CHA | J18: =VLOOKUP(H18,ID!$C$3:$D$100,2,FALSE) -> 28 | K18: Bombagem | L18: =VLOOKUP(K18,Localizacoes!$E$3:$F$100,2,FALSE) -> BBG | M18: =VLOOKUP(K18,ID!$E$3:$F$100,2,FALSE) -> BBG | N18: Electrobomba centrífuga | O18: =VLOOKUP(N18,Localizacoes!$G$3:$H$100,2,FALSE) -> EBC | P18: =VLOOKUP(N18,ID!$G$3:$H$100,2,FALSE) -> 131 | Q18: Bomba | R18: =VLOOKUP(Q18,Localizacoes!$I$3:$J$100,2,FALSE) -> BOM | S18: =VLOOKUP(Q18,ID!$I$3:$J$100,2,FALSE) -> BOM | T18: 06 | U18: Mecânica | V18: EMICA | X18: Redundância | Y18: Operacional | Z18: =Q18&" "& T18 -> Bomba 06 | AA18: 2024 | AD18: Mensal | AF18: =_xlfn.CONCAT(N18,Q18) -> Electrobomba centrífugaBomba | AG18: =VLOOKUP(AF18,Imagens!$C$2:$D$42,2,FALSE) -> 65e96125c1d11 | AH18: =_xlfn.CONCAT(Imagens!$H$2,'registo_ativo-CDs (1)'!AG18) -> assets/imagens/products/65e96125c1d11 | AI18: 45310
A19: =LEN(B19) -> 15 | B19: =CONCATENATE(G19,J19,M19,P19,S19,T19) -> CD28BBG131MOT06 | C19: =CONCATENATE(F19, "-", I19, "-", L19, "-", O19, "-", R19, "-", T19) -> CD-CHA-BBG-EBC-MOT-06 | E19: Centro distribuidor | F19: =VLOOKUP(E19,Localizacoes!$A$3:$B$100,2,FALSE) -> CD | G19: =VLOOKUP(E19,ID!$A$3:$B$100,2,FALSE) -> CD | H19: Chamanculo | I19: =VLOOKUP(H19,Localizacoes!$C$3:$D$100,2,FALSE) -> CHA | J19: =VLOOKUP(H19,ID!$C$3:$D$100,2,FALSE) -> 28 | K19: Bombagem | L19: =VLOOKUP(K19,Localizacoes!$E$3:$F$100,2,FALSE) -> BBG | M19: =VLOOKUP(K19,ID!$E$3:$F$100,2,FALSE) -> BBG | N19: Electrobomba centrífuga | O19: =VLOOKUP(N19,Localizacoes!$G$3:$H$100,2,FALSE) -> EBC | P19: =VLOOKUP(N19,ID!$G$3:$H$100,2,FALSE) -> 131 | Q19: Motor | R19: =VLOOKUP(Q19,Localizacoes!$I$3:$J$100,2,FALSE) -> MOT | S19: =VLOOKUP(Q19,ID!$I$3:$J$100,2,FALSE) -> MOT | T19: 06 | U19: Eléctrica | V19: ECHTOP | W19: Serial No:355Y0C0816-01;200kw,3000 V;46.5A;Conn:Y; 1487 R/Min;50Hz;Eff:95.4%;factor de Pontencia 0.868 | X19: Redundância | Y19: Operacional | Z19: =Q19&" "& T19 -> Motor 06 | AA19: 2024 | AD19: Mensal | AF19: =_xlfn.CONCAT(N19,Q19) -> Electrobomba centrífugaMotor | AG19: =VLOOKUP(AF19,Imagens!$C$2:$D$42,2,FALSE) -> 65d04210323a4 | AH19: =_xlfn.CONCAT(Imagens!$H$2,'registo_ativo-CDs (1)'!AG19) -> assets/imagens/products/65d04210323a4 | AI19: 45310
A20: =LEN(B20) -> 15 | B20: =CONCATENATE(G20,J20,M20,P20,S20,T20) -> CD28BBG131QEA06 | C20: =CONCATENATE(F20, "-", I20, "-", L20, "-", O20, "-", R20, "-", T20) -> CD-CHA-BBG-EBC-QEA-06 | E20: Centro distribuidor | F20: =VLOOKUP(E20,Localizacoes!$A$3:$B$100,2,FALSE) -> CD | G20: =VLOOKUP(E20,ID!$A$3:$B$100,2,FALSE) -> CD | H20: Chamanculo | I20: =VLOOKUP(H20,Localizacoes!$C$3:$D$100,2,FALSE) -> CHA | J20: =VLOOKUP(H20,ID!$C$3:$D$100,2,FALSE) -> 28 | K20: Bombagem | L20: =VLOOKUP(K20,Localizacoes!$E$3:$F$100,2,FALSE) -> BBG | M20: =VLOOKUP(K20,ID!$E$3:$F$100,2,FALSE) -> BBG | N20: Electrobomba centrífuga | O20: =VLOOKUP(N20,Localizacoes!$G$3:$H$100,2,FALSE) -> EBC | P20: =VLOOKUP(N20,ID!$G$3:$H$100,2,FALSE) -> 131 | Q20: Quadros Eléctricos de Arranque | R20: =VLOOKUP(Q20,Localizacoes!$I$3:$J$100,2,FALSE) -> QEA | S20: =VLOOKUP(Q20,ID!$I$3:$J$100,2,FALSE) -> QEA | T20: 06 | U20: Eléctrica | X20: Redundância | Y20: Operacional | Z20: =Q20&" "& T20 -> Quadros Eléctricos de Arranque 06 | AA20: 2024 | AD20: Trimestral | AF20: =_xlfn.CONCAT(N20,Q20) -> Electrobomba centrífugaQuadros Eléctricos de Arranque | AG20: =VLOOKUP(AF20,Imagens!$C$2:$D$42,2,FALSE) -> 65e8d2fa35c12 | AH20: =_xlfn.CONCAT(Imagens!$H$2,'registo_ativo-CDs (1)'!AG20) -> assets/imagens/products/65e8d2fa35c12 | AI20: 45366
A21: =LEN(B21) -> 15 | B21: =CONCATENATE(G21,J21,M21,P21,S21,T21) -> CD28BBG131VSU06 | C21: =CONCATENATE(F21, "-", I21, "-", L21, "-", O21, "-", R21, "-", T21) -> CD-CHA-BBG-EBC-VSU-06 | E21: Centro distribuidor | F21: =VLOOKUP(E21,Localizacoes!$A$3:$B$100,2,FALSE) -> CD | G21: =VLOOKUP(E21,ID!$A$3:$B$100,2,FALSE) -> CD | H21: Chamanculo | I21: =VLOOKUP(H21,Localizacoes!$C$3:$D$100,2,FALSE) -> CHA | J21: =VLOOKUP(H21,ID!$C$3:$D$100,2,FALSE) -> 28 | K21: Bombagem | L21: =VLOOKUP(K21,Localizacoes!$E$3:$F$100,2,FALSE) -> BBG | M21: =VLOOKUP(K21,ID!$E$3:$F$100,2,FALSE) -> BBG | N21: Electrobomba centrífuga | O21: =VLOOKUP(N21,Localizacoes!$G$3:$H$100,2,FALSE) -> EBC | P21: =VLOOKUP(N21,ID!$G$3:$H$100,2,FALSE) -> 131 | Q21: Válvula Sucção | R21: =VLOOKUP(Q21,Localizacoes!$I$3:$J$100,2,FALSE) -> VSU | S21: =VLOOKUP(Q21,ID!$I$3:$J$100,2,FALSE) -> VSU | T21: 06 | U21: Mecânica | X21: Redundância | Y21: Operacional | Z21: =Q21&" "& T21 -> Válvula Sucção 06 | AA21: 2024 | AD21: Trimestral | AF21: =_xlfn.CONCAT(N21,Q21) -> Electrobomba centrífugaVálvula Sucção | AG21: =VLOOKUP(AF21,Imagens!$C$2:$D$42,2,FALSE) -> 65e8cda0676b7 | AH21: =_xlfn.CONCAT(Imagens!$H$2,'registo_ativo-CDs (1)'!AG21) -> assets/imagens/products/65e8cda0676b7 | AI21: 45366
A22: =LEN(B22) -> 15 | B22: =CONCATENATE(G22,J22,M22,P22,S22,T22) -> CD28BBG131VDE06 | C22: =CONCATENATE(F22, "-", I22, "-", L22, "-", O22, "-", R22, "-", T22) -> CD-CHA-BBG-EBC-VDE-06 | E22: Centro distribuidor | F22: =VLOOKUP(E22,Localizacoes!$A$3:$B$100,2,FALSE) -> CD | G22: =VLOOKUP(E22,ID!$A$3:$B$100,2,FALSE) -> CD | H22: Chamanculo | I22: =VLOOKUP(H22,Localizacoes!$C$3:$D$100,2,FALSE) -> CHA | J22: =VLOOKUP(H22,ID!$C$3:$D$100,2,FALSE) -> 28 | K22: Bombagem | L22: =VLOOKUP(K22,Localizacoes!$E$3:$F$100,2,FALSE) -> BBG | M22: =VLOOKUP(K22,ID!$E$3:$F$100,2,FALSE) -> BBG | N22: Electrobomba centrífuga | O22: =VLOOKUP(N22,Localizacoes!$G$3:$H$100,2,FALSE) -> EBC | P22: =VLOOKUP(N22,ID!$G$3:$H$100,2,FALSE) -> 131 | Q22: Válvula Descarga | R22: =VLOOKUP(Q22,Localizacoes!$I$3:$J$100,2,FALSE) -> VDE | S22: =VLOOKUP(Q22,ID!$I$3:$J$100,2,FALSE) -> VDE | T22: 06 | U22: Mecânica | X22: Redundância | Y22: Operacional | Z22: =Q22&" "& T22 -> Válvula Descarga 06 | AA22: 2024 | AD22: Trimestral | AF22: =_xlfn.CONCAT(N22,Q22) -> Electrobomba centrífugaVálvula Descarga | AG22: =VLOOKUP(AF22,Imagens!$C$2:$D$42,2,FALSE) -> 65e8cda0676b7 | AH22: =_xlfn.CONCAT(Imagens!$H$2,'registo_ativo-CDs (1)'!AG22) -> assets/imagens/products/65e8cda0676b7 | AI22: 45366
A23: =LEN(B23) -> 15 | B23: =CONCATENATE(G23,J23,M23,P23,S23,T23) -> CD28BBG131BOM07 | C23: =CONCATENATE(F23, "-", I23, "-", L23, "-", O23, "-", R23, "-", T23) -> CD-CHA-BBG-EBC-BOM-07 | E23: Centro distribuidor | F23: =VLOOKUP(E23,Localizacoes!$A$3:$B$100,2,FALSE) -> CD | G23: =VLOOKUP(E23,ID!$A$3:$B$100,2,FALSE) -> CD | H23: Chamanculo | I23: =VLOOKUP(H23,Localizacoes!$C$3:$D$100,2,FALSE) -> CHA | J23: =VLOOKUP(H23,ID!$C$3:$D$100,2,FALSE) -> 28 | K23: Bombagem | L23: =VLOOKUP(K23,Localizacoes!$E$3:$F$100,2,FALSE) -> BBG | M23: =VLOOKUP(K23,ID!$E$3:$F$100,2,FALSE) -> BBG | N23: Electrobomba centrífuga | O23: =VLOOKUP(N23,Localizacoes!$G$3:$H$100,2,FALSE) -> EBC | P23: =VLOOKUP(N23,ID!$G$3:$H$100,2,FALSE) -> 131 | Q23: Bomba | R23: =VLOOKUP(Q23,Localizacoes!$I$3:$J$100,2,FALSE) -> BOM | S23: =VLOOKUP(Q23,ID!$I$3:$J$100,2,FALSE) -> BOM | T23: 07 | U23: Mecânica | V23: EMICA | X23: Redundância | Y23: Operacional | Z23: =Q23&" "& T23 -> Bomba 07 | AA23: 2024 | AD23: Mensal | AF23: =_xlfn.CONCAT(N23,Q23) -> Electrobomba centrífugaBomba | AG23: =VLOOKUP(AF23,Imagens!$C$2:$D$42,2,FALSE) -> 65e96125c1d11 | AH23: =_xlfn.CONCAT(Imagens!$H$2,'registo_ativo-CDs (1)'!AG23) -> assets/imagens/products/65e96125c1d11 | AI23: 45310
A24: =LEN(B24) -> 15 | B24: =CONCATENATE(G24,J24,M24,P24,S24,T24) -> CD28BBG131MOT07 | C24: =CONCATENATE(F24, "-", I24, "-", L24, "-", O24, "-", R24, "-", T24) -> CD-CHA-BBG-EBC-MOT-07 | E24: Centro distribuidor | F24: =VLOOKUP(E24,Localizacoes!$A$3:$B$100,2,FALSE) -> CD | G24: =VLOOKUP(E24,ID!$A$3:$B$100,2,FALSE) -> CD | H24: Chamanculo | I24: =VLOOKUP(H24,Localizacoes!$C$3:$D$100,2,FALSE) -> CHA | J24: =VLOOKUP(H24,ID!$C$3:$D$100,2,FALSE) -> 28 | K24: Bombagem | L24: =VLOOKUP(K24,Localizacoes!$E$3:$F$100,2,FALSE) -> BBG | M24: =VLOOKUP(K24,ID!$E$3:$F$100,2,FALSE) -> BBG | N24: Electrobomba centrífuga | O24: =VLOOKUP(N24,Localizacoes!$G$3:$H$100,2,FALSE) -> EBC | P24: =VLOOKUP(N24,ID!$G$3:$H$100,2,FALSE) -> 131 | Q24: Motor | R24: =VLOOKUP(Q24,Localizacoes!$I$3:$J$100,2,FALSE) -> MOT | S24: =VLOOKUP(Q24,ID!$I$3:$J$100,2,FALSE) -> MOT | T24: 07 | U24: Eléctrica | V24: ECHTOP | W24: Serial No:355Y0C0816-01;200kw,3000 V;46.5A;Conn:Y; 1487 R/Min;50Hz;Eff:95.4%;factor de Pontencia 0.868 | Y24: Operacional | Z24: =Q24&" "& T24 -> Motor 07 | AA24: 2024 | AD24: Mensal | AF24: =_xlfn.CONCAT(N24,Q24) -> Electrobomba centrífugaMotor | AG24: =VLOOKUP(AF24,Imagens!$C$2:$D$42,2,FALSE) -> 65d04210323a4 | AH24: =_xlfn.CONCAT(Imagens!$H$2,'registo_ativo-CDs (1)'!AG24) -> assets/imagens/products/65d04210323a4 | AI24: 45310
A25: =LEN(B25) -> 15 | B25: =CONCATENATE(G25,J25,M25,P25,S25,T25) -> CD28BBG131QEA07 | C25: =CONCATENATE(F25, "-", I25, "-", L25, "-", O25, "-", R25, "-", T25) -> CD-CHA-BBG-EBC-QEA-07 | E25: Centro distribuidor | F25: =VLOOKUP(E25,Localizacoes!$A$3:$B$100,2,FALSE) -> CD | G25: =VLOOKUP(E25,ID!$A$3:$B$100,2,FALSE) -> CD | H25: Chamanculo | I25: =VLOOKUP(H25,Localizacoes!$C$3:$D$100,2,FALSE) -> CHA | J25: =VLOOKUP(H25,ID!$C$3:$D$100,2,FALSE) -> 28 | K25: Bombagem | L25: =VLOOKUP(K25,Localizacoes!$E$3:$F$100,2,FALSE) -> BBG | M25: =VLOOKUP(K25,ID!$E$3:$F$100,2,FALSE) -> BBG | N25: Electrobomba centrífuga | O25: =VLOOKUP(N25,Localizacoes!$G$3:$H$100,2,FALSE) -> EBC | P25: =VLOOKUP(N25,ID!$G$3:$H$100,2,FALSE) -> 131 | Q25: Quadros Eléctricos de Arranque | R25: =VLOOKUP(Q25,Localizacoes!$I$3:$J$100,2,FALSE) -> QEA | S25: =VLOOKUP(Q25,ID!$I$3:$J$100,2,FALSE) -> QEA | T25: 07 | U25: Eléctrica | Y25: Operacional | Z25: =Q25&" "& T25 -> Quadros Eléctricos de Arranque 07 | AA25: 2024 | AD25: Trimestral | AF25: =_xlfn.CONCAT(N25,Q25) -> Electrobomba centrífugaQuadros Eléctricos de Arranque | AG25: =VLOOKUP(AF25,Imagens!$C$2:$D$42,2,FALSE) -> 65e8d2fa35c12 | AH25: =_xlfn.CONCAT(Imagens!$H$2,'registo_ativo-CDs (1)'!AG25) -> assets/imagens/products/65e8d2fa35c12 | AI25: 45366
A26: =LEN(B26) -> 15 | B26: =CONCATENATE(G26,J26,M26,P26,S26,T26) -> CD28BBG131VSU07 | C26: =CONCATENATE(F26, "-", I26, "-", L26, "-", O26, "-", R26, "-", T26) -> CD-CHA-BBG-EBC-VSU-07 | E26: Centro distribuidor | F26: =VLOOKUP(E26,Localizacoes!$A$3:$B$100,2,FALSE) -> CD | G26: =VLOOKUP(E26,ID!$A$3:$B$100,2,FALSE) -> CD | H26: Chamanculo | I26: =VLOOKUP(H26,Localizacoes!$C$3:$D$100,2,FALSE) -> CHA | J26: =VLOOKUP(H26,ID!$C$3:$D$100,2,FALSE) -> 28 | K26: Bombagem | L26: =VLOOKUP(K26,Localizacoes!$E$3:$F$100,2,FALSE) -> BBG | M26: =VLOOKUP(K26,ID!$E$3:$F$100,2,FALSE) -> BBG | N26: Electrobomba centrífuga | O26: =VLOOKUP(N26,Localizacoes!$G$3:$H$100,2,FALSE) -> EBC | P26: =VLOOKUP(N26,ID!$G$3:$H$100,2,FALSE) -> 131 | Q26: Válvula Sucção | R26: =VLOOKUP(Q26,Localizacoes!$I$3:$J$100,2,FALSE) -> VSU | S26: =VLOOKUP(Q26,ID!$I$3:$J$100,2,FALSE) -> VSU | T26: 07 | U26: Mecânica | X26: Redundância | Y26: Operacional | Z26: =Q26&" "& T26 -> Válvula Sucção 07 | AA26: 2024 | AD26: Trimestral | AF26: =_xlfn.CONCAT(N26,Q26) -> Electrobomba centrífugaVálvula Sucção | AG26: =VLOOKUP(AF26,Imagens!$C$2:$D$42,2,FALSE) -> 65e8cda0676b7 | AH26: =_xlfn.CONCAT(Imagens!$H$2,'registo_ativo-CDs (1)'!AG26) -> assets/imagens/products/65e8cda0676b7 | AI26: 45366
A27: =LEN(B27) -> 15 | B27: =CONCATENATE(G27,J27,M27,P27,S27,T27) -> CD28BBG131VDE07 | C27: =CONCATENATE(F27, "-", I27, "-", L27, "-", O27, "-", R27, "-", T27) -> CD-CHA-BBG-EBC-VDE-07 | E27: Centro distribuidor | F27: =VLOOKUP(E27,Localizacoes!$A$3:$B$100,2,FALSE) -> CD | G27: =VLOOKUP(E27,ID!$A$3:$B$100,2,FALSE) -> CD | H27: Chamanculo | I27: =VLOOKUP(H27,Localizacoes!$C$3:$D$100,2,FALSE) -> CHA | J27: =VLOOKUP(H27,ID!$C$3:$D$100,2,FALSE) -> 28 | K27: Bombagem | L27: =VLOOKUP(K27,Localizacoes!$E$3:$F$100,2,FALSE) -> BBG | M27: =VLOOKUP(K27,ID!$E$3:$F$100,2,FALSE) -> BBG | N27: Electrobomba centrífuga | O27: =VLOOKUP(N27,Localizacoes!$G$3:$H$100,2,FALSE) -> EBC | P27: =VLOOKUP(N27,ID!$G$3:$H$100,2,FALSE) -> 131 | Q27: Válvula Descarga | R27: =VLOOKUP(Q27,Localizacoes!$I$3:$J$100,2,FALSE) -> VDE | S27: =VLOOKUP(Q27,ID!$I$3:$J$100,2,FALSE) -> VDE | T27: 07 | U27: Mecânica | Y27: Operacional | Z27: =Q27&" "& T27 -> Válvula Descarga 07 | AA27: 2024 | AD27: Trimestral | AF27: =_xlfn.CONCAT(N27,Q27) -> Electrobomba centrífugaVálvula Descarga | AG27: =VLOOKUP(AF27,Imagens!$C$2:$D$42,2,FALSE) -> 65e8cda0676b7 | AH27: =_xlfn.CONCAT(Imagens!$H$2,'registo_ativo-CDs (1)'!AG27) -> assets/imagens/products/65e8cda0676b7 | AI27: 45366
A28: =LEN(B28) -> 15 | B28: =CONCATENATE(G28,J28,M28,P28,S28,T28) -> CD28BBG131BOM08 | C28: =CONCATENATE(F28, "-", I28, "-", L28, "-", O28, "-", R28, "-", T28) -> CD-CHA-BBG-EBC-BOM-08 | E28: Centro distribuidor | F28: =VLOOKUP(E28,Localizacoes!$A$3:$B$100,2,FALSE) -> CD | G28: =VLOOKUP(E28,ID!$A$3:$B$100,2,FALSE) -> CD | H28: Chamanculo | I28: =VLOOKUP(H28,Localizacoes!$C$3:$D$100,2,FALSE) -> CHA | J28: =VLOOKUP(H28,ID!$C$3:$D$100,2,FALSE) -> 28 | K28: Bombagem | L28: =VLOOKUP(K28,Localizacoes!$E$3:$F$100,2,FALSE) -> BBG | M28: =VLOOKUP(K28,ID!$E$3:$F$100,2,FALSE) -> BBG | N28: Electrobomba centrífuga | O28: =VLOOKUP(N28,Localizacoes!$G$3:$H$100,2,FALSE) -> EBC | P28: =VLOOKUP(N28,ID!$G$3:$H$100,2,FALSE) -> 131 | Q28: Bomba | R28: =VLOOKUP(Q28,Localizacoes!$I$3:$J$100,2,FALSE) -> BOM | S28: =VLOOKUP(Q28,ID!$I$3:$J$100,2,FALSE) -> BOM | T28: 08 | U28: Mecânica | V28: INKOA | W28: INGERSOLL DRESSER Pumps* 72230 ARDGE- France* Ano Fabrico: 2000. Type: 400LNN725* Peso: 2500 Kg* S/N: Sp17200260-02* 980 RPM* 3400m3/h* H: 65 m* P/0MA* A48CL40* L06790* Rolamentos DE e NDE: 6221 C3* Tamp: 02102-937.R1* Base: 02101-937.R1* | Y28: Operacional | Z28: =Q28&" "& T28 -> Bomba 08 | AD28: Mensal | AF28: =_xlfn.CONCAT(N28,Q28) -> Electrobomba centrífugaBomba | AG28: =VLOOKUP(AF28,Imagens!$C$2:$D$42,2,FALSE) -> 65e96125c1d11 | AH28: =_xlfn.CONCAT(Imagens!$H$2,'registo_ativo-CDs (1)'!AG28) -> assets/imagens/products/65e96125c1d11 | AI28: 45310
A29: =LEN(B29) -> 15 | B29: =CONCATENATE(G29,J29,M29,P29,S29,T29) -> CD28BBG131MOT08 | C29: =CONCATENATE(F29, "-", I29, "-", L29, "-", O29, "-", R29, "-", T29) -> CD-CHA-BBG-EBC-MOT-08 | E29: Centro distribuidor | F29: =VLOOKUP(E29,Localizacoes!$A$3:$B$100,2,FALSE) -> CD | G29: =VLOOKUP(E29,ID!$A$3:$B$100,2,FALSE) -> CD | H29: Chamanculo | I29: =VLOOKUP(H29,Localizacoes!$C$3:$D$100,2,FALSE) -> CHA | J29: =VLOOKUP(H29,ID!$C$3:$D$100,2,FALSE) -> 28 | K29: Bombagem | L29: =VLOOKUP(K29,Localizacoes!$E$3:$F$100,2,FALSE) -> BBG | M29: =VLOOKUP(K29,ID!$E$3:$F$100,2,FALSE) -> BBG | N29: Electrobomba centrífuga | O29: =VLOOKUP(N29,Localizacoes!$G$3:$H$100,2,FALSE) -> EBC | P29: =VLOOKUP(N29,ID!$G$3:$H$100,2,FALSE) -> 131 | Q29: Motor | R29: =VLOOKUP(Q29,Localizacoes!$I$3:$J$100,2,FALSE) -> MOT | S29: =VLOOKUP(Q29,ID!$I$3:$J$100,2,FALSE) -> MOT | T29: 08 | U29: Eléctrica | V29: ALSTOM | W29: ALSTOM; type: F3PXA450L/6; N⁰: 004357001; 2000 RPM; 770 KW;CosΦ: 0.85; IEC; stat: 3000V; 1808 A; ∆T80K; 3˜YCIF; IN01; M1001I. IP23; Temp: 40⁰C; F50HZ; 4300 KG. *Rolamento ZE N320MC3 | Y29: Operacional | Z29: =Q29&" "& T29 -> Motor 08 | AD29: Mensal | AF29: =_xlfn.CONCAT(N29,Q29) -> Electrobomba centrífugaMotor | AG29: =VLOOKUP(AF29,Imagens!$C$2:$D$42,2,FALSE) -> 65d04210323a4 | AH29: =_xlfn.CONCAT(Imagens!$H$2,'registo_ativo-CDs (1)'!AG29) -> assets/imagens/products/65d04210323a4 | AI29: 45310
A30: =LEN(B30) -> 15 | B30: =CONCATENATE(G30,J30,M30,P30,S30,T30) -> CD28BBG131QEA08 | C30: =CONCATENATE(F30, "-", I30, "-", L30, "-", O30, "-", R30, "-", T30) -> CD-CHA-BBG-EBC-QEA-08 | E30: Centro distribuidor | F30: =VLOOKUP(E30,Localizacoes!$A$3:$B$100,2,FALSE) -> CD | G30: =VLOOKUP(E30,ID!$A$3:$B$100,2,FALSE) -> CD | H30: Chamanculo | I30: =VLOOKUP(H30,Localizacoes!$C$3:$D$100,2,FALSE) -> CHA | J30: =VLOOKUP(H30,ID!$C$3:$D$100,2,FALSE) -> 28 | K30: Bombagem | L30: =VLOOKUP(K30,Localizacoes!$E$3:$F$100,2,FALSE) -> BBG | M30: =VLOOKUP(K30,ID!$E$3:$F$100,2,FALSE) -> BBG | N30: Electrobomba centrífuga | O30: =VLOOKUP(N30,Localizacoes!$G$3:$H$100,2,FALSE) -> EBC | P30: =VLOOKUP(N30,ID!$G$3:$H$100,2,FALSE) -> 131 | Q30: Quadros Eléctricos de Arranque | R30: =VLOOKUP(Q30,Localizacoes!$I$3:$J$100,2,FALSE) -> QEA | S30: =VLOOKUP(Q30,ID!$I$3:$J$100,2,FALSE) -> QEA | T30: 08 | U30: Eléctrica | X30: Critico | Y30: Operacional | Z30: =Q30&" "& T30 -> Quadros Eléctricos de Arranque 08 | AD30: Trimestral | AF30: =_xlfn.CONCAT(N30,Q30) -> Electrobomba centrífugaQuadros Eléctricos de Arranque | AG30: =VLOOKUP(AF30,Imagens!$C$2:$D$42,2,FALSE) -> 65e8d2fa35c12 | AH30: =_xlfn.CONCAT(Imagens!$H$2,'registo_ativo-CDs (1)'!AG30) -> assets/imagens/products/65e8d2fa35c12 | AI30: 45366
A31: =LEN(B31) -> 15 | B31: =CONCATENATE(G31,J31,M31,P31,S31,T31) -> CD28BBG131VSU08 | C31: =CONCATENATE(F31, "-", I31, "-", L31, "-", O31, "-", R31, "-", T31) -> CD-CHA-BBG-EBC-VSU-08 | E31: Centro distribuidor | F31: =VLOOKUP(E31,Localizacoes!$A$3:$B$100,2,FALSE) -> CD | G31: =VLOOKUP(E31,ID!$A$3:$B$100,2,FALSE) -> CD | H31: Chamanculo | I31: =VLOOKUP(H31,Localizacoes!$C$3:$D$100,2,FALSE) -> CHA | J31: =VLOOKUP(H31,ID!$C$3:$D$100,2,FALSE) -> 28 | K31: Bombagem | L31: =VLOOKUP(K31,Localizacoes!$E$3:$F$100,2,FALSE) -> BBG | M31: =VLOOKUP(K31,ID!$E$3:$F$100,2,FALSE) -> BBG | N31: Electrobomba centrífuga | O31: =VLOOKUP(N31,Localizacoes!$G$3:$H$100,2,FALSE) -> EBC | P31: =VLOOKUP(N31,ID!$G$3:$H$100,2,FALSE) -> 131 | Q31: Válvula Sucção | R31: =VLOOKUP(Q31,Localizacoes!$I$3:$J$100,2,FALSE) -> VSU | S31: =VLOOKUP(Q31,ID!$I$3:$J$100,2,FALSE) -> VSU | T31: 08 | U31: Mecânica | W31: Type: AD0063-2/80* Art: 2011/892* N⁰: 3700MM36216* 50 Hz* cosΦ: 0.80* IP67* 2800M* IEC85* INSUL. CL. F 3˜400V. 1.5 Km* | Y31: Operacional | Z31: =Q31&" "& T31 -> Válvula Sucção 08 | AD31: Trimestral | AF31: =_xlfn.CONCAT(N31,Q31) -> Electrobomba centrífugaVálvula Sucção | AG31: =VLOOKUP(AF31,Imagens!$C$2:$D$42,2,FALSE) -> 65e8cda0676b7 | AH31: =_xlfn.CONCAT(Imagens!$H$2,'registo_ativo-CDs (1)'!AG31) -> assets/imagens/products/65e8cda0676b7 | AI31: 45366
A32: =LEN(B32) -> 15 | B32: =CONCATENATE(G32,J32,M32,P32,S32,T32) -> CD28BBG131VDE08 | C32: =CONCATENATE(F32, "-", I32, "-", L32, "-", O32, "-", R32, "-", T32) -> CD-CHA-BBG-EBC-VDE-08 | E32: Centro distribuidor | F32: =VLOOKUP(E32,Localizacoes!$A$3:$B$100,2,FALSE) -> CD | G32: =VLOOKUP(E32,ID!$A$3:$B$100,2,FALSE) -> CD | H32: Chamanculo | I32: =VLOOKUP(H32,Localizacoes!$C$3:$D$100,2,FALSE) -> CHA | J32: =VLOOKUP(H32,ID!$C$3:$D$100,2,FALSE) -> 28 | K32: Bombagem | L32: =VLOOKUP(K32,Localizacoes!$E$3:$F$100,2,FALSE) -> BBG | M32: =VLOOKUP(K32,ID!$E$3:$F$100,2,FALSE) -> BBG | N32: Electrobomba centrífuga | O32: =VLOOKUP(N32,Localizacoes!$G$3:$H$100,2,FALSE) -> EBC | P32: =VLOOKUP(N32,ID!$G$3:$H$100,2,FALSE) -> 131 | Q32: Válvula Descarga | R32: =VLOOKUP(Q32,Localizacoes!$I$3:$J$100,2,FALSE) -> VDE | S32: =VLOOKUP(Q32,ID!$I$3:$J$100,2,FALSE) -> VDE | T32: 08 | U32: Mecânica | Y32: Operacional | Z32: =Q32&" "& T32 -> Válvula Descarga 08 | AD32: Trimestral | AF32: =_xlfn.CONCAT(N32,Q32) -> Electrobomba centrífugaVálvula Descarga | AG32: =VLOOKUP(AF32,Imagens!$C$2:$D$42,2,FALSE) -> 65e8cda0676b7 | AH32: =_xlfn.CONCAT(Imagens!$H$2,'registo_ativo-CDs (1)'!AG32) -> assets/imagens/products/65e8cda0676b7 | AI32: 45366
A33: =LEN(B33) -> 15 | B33: =CONCATENATE(G33,J33,M33,P33,S33,T33) -> CD28BBG131BOM09 | C33: =CONCATENATE(F33, "-", I33, "-", L33, "-", O33, "-", R33, "-", T33) -> CD-CHA-BBG-EBC-BOM-09 | E33: Centro distribuidor | F33: =VLOOKUP(E33,Localizacoes!$A$3:$B$100,2,FALSE) -> CD | G33: =VLOOKUP(E33,ID!$A$3:$B$100,2,FALSE) -> CD | H33: Chamanculo | I33: =VLOOKUP(H33,Localizacoes!$C$3:$D$100,2,FALSE) -> CHA | J33: =VLOOKUP(H33,ID!$C$3:$D$100,2,FALSE) -> 28 | K33: Bombagem | L33: =VLOOKUP(K33,Localizacoes!$E$3:$F$100,2,FALSE) -> BBG | M33: =VLOOKUP(K33,ID!$E$3:$F$100,2,FALSE) -> BBG | N33: Electrobomba centrífuga | O33: =VLOOKUP(N33,Localizacoes!$G$3:$H$100,2,FALSE) -> EBC | P33: =VLOOKUP(N33,ID!$G$3:$H$100,2,FALSE) -> 131 | Q33: Bomba | R33: =VLOOKUP(Q33,Localizacoes!$I$3:$J$100,2,FALSE) -> BOM | S33: =VLOOKUP(Q33,ID!$I$3:$J$100,2,FALSE) -> BOM | T33: 09 | U33: Mecânica | V33: GRUNDFOS | W33: TP 300-670/4 A-F-B-DBUE* Model: A96639190 P2064900163* Q:1300m³/h* H:50 m* F:1488 RPM* P/T: 25/40 Bar/⁰Cmax* CE96145329* 96106185* S400-18* VDP P156 30* ; 50.9m* | Y33: Operacional | Z33: =Q33&" "& T33 -> Bomba 09 | AA33: 2007 | AD33: Mensal | AF33: =_xlfn.CONCAT(N33,Q33) -> Electrobomba centrífugaBomba | AG33: =VLOOKUP(AF33,Imagens!$C$2:$D$42,2,FALSE) -> 65e96125c1d11 | AH33: =_xlfn.CONCAT(Imagens!$H$2,'registo_ativo-CDs (1)'!AG33) -> assets/imagens/products/65e96125c1d11 | AI33: 45310
A34: =LEN(B34) -> 15 | B34: =CONCATENATE(G34,J34,M34,P34,S34,T34) -> CD28BBG131MOT09 | C34: =CONCATENATE(F34, "-", I34, "-", L34, "-", O34, "-", R34, "-", T34) -> CD-CHA-BBG-EBC-MOT-09 | E34: Centro distribuidor | F34: =VLOOKUP(E34,Localizacoes!$A$3:$B$100,2,FALSE) -> CD | G34: =VLOOKUP(E34,ID!$A$3:$B$100,2,FALSE) -> CD | H34: Chamanculo | I34: =VLOOKUP(H34,Localizacoes!$C$3:$D$100,2,FALSE) -> CHA | J34: =VLOOKUP(H34,ID!$C$3:$D$100,2,FALSE) -> 28 | K34: Bombagem | L34: =VLOOKUP(K34,Localizacoes!$E$3:$F$100,2,FALSE) -> BBG | M34: =VLOOKUP(K34,ID!$E$3:$F$100,2,FALSE) -> BBG | N34: Electrobomba centrífuga | O34: =VLOOKUP(N34,Localizacoes!$G$3:$H$100,2,FALSE) -> EBC | P34: =VLOOKUP(N34,ID!$G$3:$H$100,2,FALSE) -> 131 | Q34: Motor | R34: =VLOOKUP(Q34,Localizacoes!$I$3:$J$100,2,FALSE) -> MOT | S34: =VLOOKUP(Q34,ID!$I$3:$J$100,2,FALSE) -> MOT | T34: 09 | U34: Eléctrica | V34: SIEMENS | W34: 220v-240v; 60 hz;3000Υ; D-90441; 60 A; Kw 250; cosΦ:0.84. 1480 rpm. 3̃ ˜Mot. 1LA4.312- 4AN34-Z; rotor: SQUCQGE; THCI/6. IP55. N⁰: N-UN1188395010003 12006IMV1.* Rolamento 6218 & 6220 | Y34: Operacional | Z34: =Q34&" "& T34 -> Motor 09 | AA34: 2007 | AD34: Mensal | AF34: =_xlfn.CONCAT(N34,Q34) -> Electrobomba centrífugaMotor | AG34: =VLOOKUP(AF34,Imagens!$C$2:$D$42,2,FALSE) -> 65d04210323a4 | AH34: =_xlfn.CONCAT(Imagens!$H$2,'registo_ativo-CDs (1)'!AG34) -> assets/imagens/products/65d04210323a4 | AI34: 45310
A35: =LEN(B35) -> 15 | B35: =CONCATENATE(G35,J35,M35,P35,S35,T35) -> CD28BBG131QEA09 | C35: =CONCATENATE(F35, "-", I35, "-", L35, "-", O35, "-", R35, "-", T35) -> CD-CHA-BBG-EBC-QEA-09 | E35: Centro distribuidor | F35: =VLOOKUP(E35,Localizacoes!$A$3:$B$100,2,FALSE) -> CD | G35: =VLOOKUP(E35,ID!$A$3:$B$100,2,FALSE) -> CD | H35: Chamanculo | I35: =VLOOKUP(H35,Localizacoes!$C$3:$D$100,2,FALSE) -> CHA | J35: =VLOOKUP(H35,ID!$C$3:$D$100,2,FALSE) -> 28 | K35: Bombagem | L35: =VLOOKUP(K35,Localizacoes!$E$3:$F$100,2,FALSE) -> BBG | M35: =VLOOKUP(K35,ID!$E$3:$F$100,2,FALSE) -> BBG | N35: Electrobomba centrífuga | O35: =VLOOKUP(N35,Localizacoes!$G$3:$H$100,2,FALSE) -> EBC | P35: =VLOOKUP(N35,ID!$G$3:$H$100,2,FALSE) -> 131 | Q35: Quadros Eléctricos de Arranque | R35: =VLOOKUP(Q35,Localizacoes!$I$3:$J$100,2,FALSE) -> QEA | S35: =VLOOKUP(Q35,ID!$I$3:$J$100,2,FALSE) -> QEA | T35: 09 | U35: Eléctrica | Y35: Operacional | Z35: =Q35&" "& T35 -> Quadros Eléctricos de Arranque 09 | AA35: 2007 | AD35: Trimestral | AF35: =_xlfn.CONCAT(N35,Q35) -> Electrobomba centrífugaQuadros Eléctricos de Arranque | AG35: =VLOOKUP(AF35,Imagens!$C$2:$D$42,2,FALSE) -> 65e8d2fa35c12 | AH35: =_xlfn.CONCAT(Imagens!$H$2,'registo_ativo-CDs (1)'!AG35) -> assets/imagens/products/65e8d2fa35c12 | AI35: 45366
A36: =LEN(B36) -> 15 | B36: =CONCATENATE(G36,J36,M36,P36,S36,T36) -> CD28BBG131VSU09 | C36: =CONCATENATE(F36, "-", I36, "-", L36, "-", O36, "-", R36, "-", T36) -> CD-CHA-BBG-EBC-VSU-09 | E36: Centro distribuidor | F36: =VLOOKUP(E36,Localizacoes!$A$3:$B$100,2,FALSE) -> CD | G36: =VLOOKUP(E36,ID!$A$3:$B$100,2,FALSE) -> CD | H36: Chamanculo | I36: =VLOOKUP(H36,Localizacoes!$C$3:$D$100,2,FALSE) -> CHA | J36: =VLOOKUP(H36,ID!$C$3:$D$100,2,FALSE) -> 28 | K36: Bombagem | L36: =VLOOKUP(K36,Localizacoes!$E$3:$F$100,2,FALSE) -> BBG | M36: =VLOOKUP(K36,ID!$E$3:$F$100,2,FALSE) -> BBG | N36: Electrobomba centrífuga | O36: =VLOOKUP(N36,Localizacoes!$G$3:$H$100,2,FALSE) -> EBC | P36: =VLOOKUP(N36,ID!$G$3:$H$100,2,FALSE) -> 131 | Q36: Válvula Sucção | R36: =VLOOKUP(Q36,Localizacoes!$I$3:$J$100,2,FALSE) -> VSU | S36: =VLOOKUP(Q36,ID!$I$3:$J$100,2,FALSE) -> VSU | T36: 09 | U36: Mecânica | W36: Type: SZ45T-16* ZAY882* T1ANSNGGV. DN 450* PN16/855150* | Y36: Operacional | Z36: =Q36&" "& T36 -> Válvula Sucção 09 | AA36: 2007 | AD36: Trimestral | AF36: =_xlfn.CONCAT(N36,Q36) -> Electrobomba centrífugaVálvula Sucção | AG36: =VLOOKUP(AF36,Imagens!$C$2:$D$42,2,FALSE) -> 65e8cda0676b7 | AH36: =_xlfn.CONCAT(Imagens!$H$2,'registo_ativo-CDs (1)'!AG36) -> assets/imagens/products/65e8cda0676b7 | AI36: 45366
A37: =LEN(B37) -> 15 | B37: =CONCATENATE(G37,J37,M37,P37,S37,T37) -> CD28BBG131VDE09 | C37: =CONCATENATE(F37, "-", I37, "-", L37, "-", O37, "-", R37, "-", T37) -> CD-CHA-BBG-EBC-VDE-09 | E37: Centro distribuidor | F37: =VLOOKUP(E37,Localizacoes!$A$3:$B$100,2,FALSE) -> CD | G37: =VLOOKUP(E37,ID!$A$3:$B$100,2,FALSE) -> CD | H37: Chamanculo | I37: =VLOOKUP(H37,Localizacoes!$C$3:$D$100,2,FALSE) -> CHA | J37: =VLOOKUP(H37,ID!$C$3:$D$100,2,FALSE) -> 28 | K37: Bombagem | L37: =VLOOKUP(K37,Localizacoes!$E$3:$F$100,2,FALSE) -> BBG | M37: =VLOOKUP(K37,ID!$E$3:$F$100,2,FALSE) -> BBG | N37: Electrobomba centrífuga | O37: =VLOOKUP(N37,Localizacoes!$G$3:$H$100,2,FALSE) -> EBC | P37: =VLOOKUP(N37,ID!$G$3:$H$100,2,FALSE) -> 131 | Q37: Válvula Descarga | R37: =VLOOKUP(Q37,Localizacoes!$I$3:$J$100,2,FALSE) -> VDE | S37: =VLOOKUP(Q37,ID!$I$3:$J$100,2,FALSE) -> VDE | T37: 09 | U37: Mecânica | W37: Type: 1024VB* Number Product: 2006/09* GEAR Rabie: 812. Max. Toque: 2500-4100N/m. | Y37: Operacional | Z37: =Q37&" "& T37 -> Válvula Descarga 09 | AA37: 2007 | AD37: Trimestral | AF37: =_xlfn.CONCAT(N37,Q37) -> Electrobomba centrífugaVálvula Descarga | AG37: =VLOOKUP(AF37,Imagens!$C$2:$D$42,2,FALSE) -> 65e8cda0676b7 | AH37: =_xlfn.CONCAT(Imagens!$H$2,'registo_ativo-CDs (1)'!AG37) -> assets/imagens/products/65e8cda0676b7 | AI37: 45366
A38: =LEN(B38) -> 15 | B38: =CONCATENATE(G38,J38,M38,P38,S38,T38) -> CD28BBG131BOM10 | C38: =CONCATENATE(F38, "-", I38, "-", L38, "-", O38, "-", R38, "-", T38) -> CD-CHA-BBG-EBC-BOM-10 | E38: Centro distribuidor | F38: =VLOOKUP(E38,Localizacoes!$A$3:$B$100,2,FALSE) -> CD | G38: =VLOOKUP(E38,ID!$A$3:$B$100,2,FALSE) -> CD | H38: Chamanculo | I38: =VLOOKUP(H38,Localizacoes!$C$3:$D$100,2,FALSE) -> CHA | J38: =VLOOKUP(H38,ID!$C$3:$D$100,2,FALSE) -> 28 | K38: Bombagem | L38: =VLOOKUP(K38,Localizacoes!$E$3:$F$100,2,FALSE) -> BBG | M38: =VLOOKUP(K38,ID!$E$3:$F$100,2,FALSE) -> BBG | N38: Electrobomba centrífuga | O38: =VLOOKUP(N38,Localizacoes!$G$3:$H$100,2,FALSE) -> EBC | P38: =VLOOKUP(N38,ID!$G$3:$H$100,2,FALSE) -> 131 | Q38: Bomba | R38: =VLOOKUP(Q38,Localizacoes!$I$3:$J$100,2,FALSE) -> BOM | S38: =VLOOKUP(Q38,ID!$I$3:$J$100,2,FALSE) -> BOM | T38: 10 | U38: Mecânica | V38: GRUNDFOS | W38: TP 300-670/4 A-F-B-DBUE* Model: A96639190 P2064900163* Q:1300m³/h* H:50 m* F:1488 RPM* P/T: 25/40 Bar/⁰Cmax* CE96145329* 96106185* S400-18* VDP P156 30* ; 50.9m* | Y38: Operacional | Z38: =Q38&" "& T38 -> Bomba 10 | AA38: 2007 | AD38: Mensal | AF38: =_xlfn.CONCAT(N38,Q38) -> Electrobomba centrífugaBomba | AG38: =VLOOKUP(AF38,Imagens!$C$2:$D$42,2,FALSE) -> 65e96125c1d11 | AH38: =_xlfn.CONCAT(Imagens!$H$2,'registo_ativo-CDs (1)'!AG38) -> assets/imagens/products/65e96125c1d11 | AI38: 45310
A39: =LEN(B39) -> 15 | B39: =CONCATENATE(G39,J39,M39,P39,S39,T39) -> CD28BBG131MOT10 | C39: =CONCATENATE(F39, "-", I39, "-", L39, "-", O39, "-", R39, "-", T39) -> CD-CHA-BBG-EBC-MOT-10 | E39: Centro distribuidor | F39: =VLOOKUP(E39,Localizacoes!$A$3:$B$100,2,FALSE) -> CD | G39: =VLOOKUP(E39,ID!$A$3:$B$100,2,FALSE) -> CD | H39: Chamanculo | I39: =VLOOKUP(H39,Localizacoes!$C$3:$D$100,2,FALSE) -> CHA | J39: =VLOOKUP(H39,ID!$C$3:$D$100,2,FALSE) -> 28 | K39: Bombagem | L39: =VLOOKUP(K39,Localizacoes!$E$3:$F$100,2,FALSE) -> BBG | M39: =VLOOKUP(K39,ID!$E$3:$F$100,2,FALSE) -> BBG | N39: Electrobomba centrífuga | O39: =VLOOKUP(N39,Localizacoes!$G$3:$H$100,2,FALSE) -> EBC | P39: =VLOOKUP(N39,ID!$G$3:$H$100,2,FALSE) -> 131 | Q39: Motor | R39: =VLOOKUP(Q39,Localizacoes!$I$3:$J$100,2,FALSE) -> MOT | S39: =VLOOKUP(Q39,ID!$I$3:$J$100,2,FALSE) -> MOT | T39: 10 | U39: Eléctrica | V39: SIEMENS | W39: 220v-240v; 60 hz;3000Υ; D-90441; 60 A; Kw 250; cosΦ:0.84. 1480 rpm. 3̃ ˜Mot. 1LA4.312- 4AN34-Z; rotor: SQUCQGE; THCI/6. IP55. N⁰: N-UN1188395010003 12006IMV1.* Rolamento 6218 & 6220 | X39: Critico | Y39: Operacional | Z39: =Q39&" "& T39 -> Motor 10 | AA39: 2007 | AD39: Mensal | AF39: =_xlfn.CONCAT(N39,Q39) -> Electrobomba centrífugaMotor | AG39: =VLOOKUP(AF39,Imagens!$C$2:$D$42,2,FALSE) -> 65d04210323a4 | AH39: =_xlfn.CONCAT(Imagens!$H$2,'registo_ativo-CDs (1)'!AG39) -> assets/imagens/products/65d04210323a4 | AI39: 45310
A40: =LEN(B40) -> 15 | B40: =CONCATENATE(G40,J40,M40,P40,S40,T40) -> CD28BBG131QEA10 | C40: =CONCATENATE(F40, "-", I40, "-", L40, "-", O40, "-", R40, "-", T40) -> CD-CHA-BBG-EBC-QEA-10 | E40: Centro distribuidor | F40: =VLOOKUP(E40,Localizacoes!$A$3:$B$100,2,FALSE) -> CD | G40: =VLOOKUP(E40,ID!$A$3:$B$100,2,FALSE) -> CD | H40: Chamanculo | I40: =VLOOKUP(H40,Localizacoes!$C$3:$D$100,2,FALSE) -> CHA | J40: =VLOOKUP(H40,ID!$C$3:$D$100,2,FALSE) -> 28 | K40: Bombagem | L40: =VLOOKUP(K40,Localizacoes!$E$3:$F$100,2,FALSE) -> BBG | M40: =VLOOKUP(K40,ID!$E$3:$F$100,2,FALSE) -> BBG | N40: Electrobomba centrífuga | O40: =VLOOKUP(N40,Localizacoes!$G$3:$H$100,2,FALSE) -> EBC | P40: =VLOOKUP(N40,ID!$G$3:$H$100,2,FALSE) -> 131 | Q40: Quadros Eléctricos de Arranque | R40: =VLOOKUP(Q40,Localizacoes!$I$3:$J$100,2,FALSE) -> QEA | S40: =VLOOKUP(Q40,ID!$I$3:$J$100,2,FALSE) -> QEA | T40: 10 | U40: Eléctrica | Y40: Operacional | Z40: =Q40&" "& T40 -> Quadros Eléctricos de Arranque 10 | AA40: 2007 | AD40: Trimestral | AF40: =_xlfn.CONCAT(N40,Q40) -> Electrobomba centrífugaQuadros Eléctricos de Arranque | AG40: =VLOOKUP(AF40,Imagens!$C$2:$D$42,2,FALSE) -> 65e8d2fa35c12 | AH40: =_xlfn.CONCAT(Imagens!$H$2,'registo_ativo-CDs (1)'!AG40) -> assets/imagens/products/65e8d2fa35c12 | AI40: 45366
...

Sheet Checklist
A1: Grupo | B1: Nome do Checklist | C1: ID_EQUIPAMENTO | D1: COD_EQUIPAMENTO | E1: ID do Checklist
A2: Actuador | B2: Actuador Eléctrico | C2: =VLOOKUP(B2,[1]ID!$C$3:$D$100,2,FALSE) -> AEL | D2: Actuador Actuador Eléctrico | E2: 100AEL
A3: Actuador Eléctrico | B3: Actuador Eléctrico | C3: =VLOOKUP(B3,[1]ID!$C$3:$D$100,2,FALSE) -> AEL | D3: Actuador Eléctrico Actuador Eléctrico | E3: 102AEL
A4: Agua de serviço | B4: Actuador Eléctrico | C4: =VLOOKUP(B4,[1]ID!$C$3:$D$100,2,FALSE) -> AEL | D4: Agua de serviço Actuador Eléctrico | E4: 106AEL
A5: Agua filtrada | B5: Actuador Eléctrico | C5: =VLOOKUP(B5,[1]ID!$C$3:$D$100,2,FALSE) -> AEL | D5: Agua filtrada Actuador Eléctrico | E5: 107AEL
A6: Caixa de Entrada | B6: Actuador Eléctrico | C6: =VLOOKUP(B6,[1]ID!$C$3:$D$100,2,FALSE) -> AEL | D6: Caixa de Entrada Actuador Eléctrico | E6: 116AEL
A7: Caixa de Saída | B7: Actuador Eléctrico | C7: =VLOOKUP(B7,[1]ID!$C$3:$D$100,2,FALSE) -> AEL | D7: Caixa de Saída Actuador Eléctrico | E7: 117AEL
A8: Electrobomba centrífuga | B8: Actuador Eléctrico | C8: =VLOOKUP(B8,[1]ID!$C$3:$D$100,2,FALSE) -> AEL | D8: Electrobomba centrífuga Actuador Eléctrico | E8: 131AEL
A9: Electrobomba Doseadora de Diafragma | B9: Actuador Eléctrico | C9: =VLOOKUP(B9,[1]ID!$C$3:$D$100,2,FALSE) -> AEL | D9: Electrobomba Doseadora de Diafragma Actuador Eléctrico | E9: 133AEL
A10: Electrobomba Submersível | B10: Actuador Eléctrico | C10: =VLOOKUP(B10,[1]ID!$C$3:$D$100,2,FALSE) -> AEL | D10: Electrobomba Submersível Actuador Eléctrico | E10: 135AEL
A11: Válvula | B11: Actuador Eléctrico | C11: =VLOOKUP(B11,[1]ID!$C$3:$D$100,2,FALSE) -> AEL | D11: Válvula Actuador Eléctrico | E11: 176AEL
A12: Agua de lavagem | B12: Actuador Pneumático | C12: =VLOOKUP(B12,[1]ID!$C$3:$D$100,2,FALSE) -> AEP | D12: Agua de lavagem Actuador Pneumático | E12: 104AEP
A13: Agua filtrada | B13: Actuador Pneumático | C13: =VLOOKUP(B13,[1]ID!$C$3:$D$100,2,FALSE) -> AEP | D13: Agua filtrada Actuador Pneumático | E13: 107AEP
... A30: Quadro Eléctrico | B30: Banco de Capacitores | C30: =VLOOKUP(B30,[1]ID!$C$3:$D$100,2,FALSE) -> BCA | D30: Quadro Eléctrico Banco de Capacitores | E30: 152BCA
A31: Banco de Capacitores | B31: Banco de Capacitores | C31: Banco de Capacitores | D31: Banco de Capacitores Quadro eléctrico | E31: 113QEL
A32: Electrobomba de Esgoto | B32: Boia | C32: =VLOOKUP(B32,[1]ID!$C$3:$D$100,2,FALSE) -> BOI | D32: Electrobomba de Esgoto Boia | E32: 132BOI
A33: Bomba de Óleo | B33: Electrobomba Doseadora de parafuso | C33: =VLOOKUP(B33,[1]ID!$C$3:$D$100,2,FALSE) -> #N/A | D33: Bomba de Óleo Bomba | E33: 115BOM
A34: Agitador | B34: Caixa de Engrenagem | C34: =VLOOKUP(B34,[1]ID!$C$3:$D$100,2,FALSE) -> CEN | D34: Agitador Caixa de Engrenagem | E34: 103CEN
A35: Raspador de Lamas 1 | B35: Caixa de Engrenagem | C35: =VLOOKUP(B35,[1]ID!$C$3:$D$100,2,FALSE) -> CEN | D35: Raspador de Lamas 1 Caixa de Engrenagem | E35: 153CEN
A36: Raspador de Lamas 2 | B36: Caixa de Engrenagem | C36: =VLOOKUP(B36,[1]ID!$C$3:$D$100,2,FALSE) -> CEN | D36: Raspador de Lamas 2 Caixa de Engrenagem | E36: 154CEN
A37: Regulador | B37: Caixa de Parcialização | C37: =VLOOKUP(B37,[1]ID!$C$3:$D$100,2,FALSE) -> CPA | D37: Regulador Caixa de Parcialização | E37: 157CPA
A38: Electrobomba centrífuga | B38: Canalização Eléctrica | C38: =VLOOKUP(B38,[1]ID!$C$3:$D$100,2,FALSE) -> CAN | D38: Electrobomba centrífuga Canalização Eléctrica | E38: 131CAN
A39: Furo | B39: Canalização Eléctrica | C39: =VLOOKUP(B39,[1]ID!$C$3:$D$100,2,FALSE) -> CAN | D39: Furo Canalização Eléctrica | E39: 141CAN
A40: Quadro Eléctrico | B40: Canalização Eléctrica | C40: =VLOOKUP(B40,[1]ID!$C$3:$D$100,2,FALSE) -> CAN | D40: Quadro Eléctrico Canalização Eléctrica | E40: 152CAN
A41: Tanque de Compensação | B41: Canalização Eléctrica | C41: =VLOOKUP(B41,[1]ID!$C$3:$D$100,2,FALSE) -> CAN | D41: Tanque de Compensação Canalização Eléctrica | E41: 170CAN
A42: Actuador Eléctrico | B42: Comporta | C42: =VLOOKUP(B42,[1]ID!$C$3:$D$100,2,FALSE) -> COM | D42: Actuador Eléctrico Comporta | E42: 102COM
A43: Caixa de Entrada | B43: Comporta | C43: =VLOOKUP(B43,[1]ID!$C$3:$D$100,2,FALSE) -> COM | D43: Caixa de Entrada Comporta | E43: 116COM
... A180: Vibrador de cal | B180: Vibrador de Cal | C180: =VLOOKUP(B180,[1]ID!$C$3:$D$100,2,FALSE) -> VCA | D180: Vibrador de cal Vibrador de Cal | E180: 178VCA

Sheet Localizacoes
A1: Zona | C1: Instalação | E1: Sistema | G1: Grupo | I1: Equipamento | K1: Ordem do equipamento
B2: Cod | D2: Cod | F2: Cod | H2: Cod | J2: Cod
A3: Adução | B3: ADU | C3: Alto Maé | D3: AM | E3: Agua Bruta | F3: AGB | G3: Actuador | H3: ACT | I3: Actuador Eléctrico | J3: AEL | P3: =CONCATENATE(B3, "-", D3, "-", H27, "-", H3, "-", J3, "-", K3) -> ADU-AM-CLC-ACT-AEL-
A4: Centro distribuidor | B4: CD | C4: Bacia de Equalização de Lamas | D4: BEL | E4: Agua de lavagem | F4: AGL | G4: Analisador | H4: ACL | I4: Actuador Pneumático | J4: AEP | P4: =CONCATENATE(B4, "-", D4, "-", H29, "-", H4, "-", J4, "-", K4) -> CD-BEL-CPC-ACL-AEP-
A5: ETA Sabié | B5: ETAS | C5: Bacia de sedimentação | D5: BSD | E5: Agua de refrigeração | F5: AGR | G5: Actuador Eléctrico | H5: AEL | I5: Alimentador | J5: ALM | P5: =CONCATENATE(B5, "-", D5, "-", F59, "-", H5, "-", J5, "-", K5) -> ETAS-BSD-STC-AEL-ALM-
A6: ETA Umbeluzi | B6: ETAU | C6: Belo-Horizonte | D6: BH | E6: Agua de serviço | F6: AGS | G6: Agitador | H6: AGI | I6: Analisador de cloro | J6: ACL | P6: =CONCATENATE(B6, "-", D6, "-", F6, "-", H6, "-", J6, "-", K6) -> ETAU-BH-AGS-AGI-ACL-
A7: Pequeno sistema | B7: PSAA | C7: Bloco Administrativo | D7: BA | E7: Agua Filtrada | F7: AGF | G7: Agua de lavagem | H7: AGL | I7: Analisador de Oxigénio | J7: AOX | P7: =CONCATENATE(D24, "-", D7, "-", F7, "-", H7, "-", J7, "-", K7) -> EQ-BA-AGF-AGL-AOX-
C8: Boane | D8: BOA | E8: Agua Tratada | F8: AGT | G8: Agua de refrigeração | H8: AGR | I8: Analisador de Ozono | J8: AOZ | P8: =CONCATENATE(B8, "-", D8, "-", H28, "-",#REF!, "-", J8, "-", K8) -> #REF!
C9: Caixa de Entrada | D9: ENT | E9: Amortecedor de choque hidráulico | F9: ACH | G9: Agua de serviço | H9: AGS | I9: Analisador de pH | J9: APH | P9: =CONCATENATE(B9, "-", D9, "-", F9, "-",#REF!, "-", J9, "-", K9) -> #REF!
C10: Caixas de Inspecção | D10: INS | E10: Ar de lavagem | F10: ARL | G10: Agua filtrada | H10: AGF | I10: Analisador de Turvação | J10: ATU | P10: =CONCATENATE(B10, "-", D10, "-", F10, "-", H10, "-", J10, "-", K10) -> -INS-ARL-AGF-ATU-
C11: Câmara de Mistura 1 | D11: CM1 | E11: Bacia de Equalização de Lamas | F11: BEL | G11: Agua motriz | H11: AGM | I11: Balança | J11: BAL | P11: =CONCATENATE(B11, "-", D11, "-", F11, "-", H11, "-", J11, "-", K11) -> -CM1-BEL-AGM-BAL-
C12: Câmara de Mistura 2 | D12: CM2 | E12: Bacia de sedimentação | F12: BSD | G12: Alimentador | H12: ALM | I12: Banco de Baterias | J12: BBA | P12: =CONCATENATE(B12, "-", D12, "-", F12, "-", H12, "-", J12, "-", K12) -> -CM2-BSD-ALM-BBA-
C13: Campo de furos da vila olimpica | D13: CFVO | E13: Bombagem | F13: BBG | G13: Ar de lavagem | H13: ARL | I13: Banco de Capacitores | J13: BCA | P13: =CONCATENATE(B13, "-", D13, "-", F13, "-", H13, "-", J13, "-", K13) -> -CFVO-BBG-ARL-BCA-
C14: Campo de furos de Intaka Norte | D14: CFIN | E14: Caixa de Entrada | F14: ENT | G14: Balança | H14: BAL | I14: Boia | J14: BOI | P14: =CONCATENATE(B14, "-", D14, "-", F14, "-", H14, "-", J14, "-", K14) -> -CFIN-ENT-BAL-BOI-
C15: Campo de furos de Intaka Sul | D15: CFIS | E15: Câmara de mistura rápida | F15: CMR | G15: Banco de Baterias | H15: BBA | I15: Bomba | J15: BOM | P15: =CONCATENATE(B15, "-", D15, "-", F15, "-", H15, "-", J15, "-", K15) -> -CFIS-CMR-BBA-BOM-
C16: Campo de furos de Katembe | D16: CFK | E16: Câmara mistura lenta | F16: CML | G16: Banco de Capacitores | H16: BCA | I16: Caixa de Engrenagem | J16: CEN | P16: =CONCATENATE(B16, "-", D16, "-", F16, "-", J18, "-", J16, "-", K16) -> -CFK-CML-CAN-CEN-
C17: Captação | D17: CPT | E17: Canalização Eléctrica | F17: CAN | G17: Boia | H17: BOI | I17: Caixa de Parcialização | J17: CPA | P17: =CONCATENATE(B17, "-", D17, "-", F17, "-", H17, "-", J17, "-", K17) -> -CPT-CAN-BOI-CPA-
C18: Captação 1 | D18: CPT1 | E18: Cisterna | F18: CTN | G18: Bomba de Óleo | H18: BOO | I18: Canalização Eléctrica | J18: CAN | P18: =CONCATENATE(B18, "-", D18, "-", F18, "-", H18, "-",#REF!, "-", K18) -> #REF!
C19: Captação 2 | D19: CPT2 | E19: Clarificador de Agua de Lavagem | F19: CAL | G19: Caixa de Entrada | H19: ENT | I19: Carregador de baterias | J19: CBA | P19: =CONCATENATE(B19, "-", D19, "-", F19, "-", H19, "-", J19, "-", K19) -> -CPT2-CAL-ENT-CBA-
C20: Captação 3 | D20: CPT3 | E20: Cloragem | F20: CLO | G20: Caixa de Saída | H20: SAI | I20: Choque Hidráulico | J20: CHO | P20: =CONCATENATE(B20, "-", D20, "-", F20, "-", H20, "-", J20, "-", K20) -> -CPT3-CLO-SAI-CHO-
